{"3f4d1291f67c4cd8748668c4b83c4596":{"statistic":{"failed":0,"broken":1,"skipped":0,"passed":0,"unknown":0,"total":1},"items":[{"uid":"915ac21d5b427430","reportUrl":"https://alyaothman14.github.io/selenium-python/2//#testresult/915ac21d5b427430","status":"broken","statusDetails":"urllib3.exceptions.MaxRetryError: HTTPConnectionPool(host='localhost', port=49187): Max retries exceeded with url: /session/b067340fc1b386a94bfc2005b0dd1a35/window (Caused by NewConnectionError('<urllib3.connection.HTTPConnection object at 0x7f75b436c910>: Failed to establish a new connection: [Errno 111] Connection refused'))","time":{"start":1683292705621,"stop":1683292706599,"duration":978}}]},"326de79410bf5e80a41e2bbea3e523a5":{"statistic":{"failed":0,"broken":1,"skipped":0,"passed":0,"unknown":0,"total":1},"items":[{"uid":"770725cee1530d8a","reportUrl":"https://alyaothman14.github.io/selenium-python/2//#testresult/770725cee1530d8a","status":"broken","statusDetails":"urllib3.exceptions.MaxRetryError: HTTPConnectionPool(host='localhost', port=37515): Max retries exceeded with url: /session/46a86cb174e1acde8b6c399ab7f23489/window (Caused by NewConnectionError('<urllib3.connection.HTTPConnection object at 0x7f75b31b9fc0>: Failed to establish a new connection: [Errno 111] Connection refused'))","time":{"start":1683292749059,"stop":1683292750610,"duration":1551}}]},"ce62b6e95f8e8da009fe6f309ba4fc9a":{"statistic":{"failed":0,"broken":1,"skipped":0,"passed":0,"unknown":0,"total":1},"items":[{"uid":"5541f12628d0b81c","reportUrl":"https://alyaothman14.github.io/selenium-python/2//#testresult/5541f12628d0b81c","status":"broken","statusDetails":"selenium.common.exceptions.TimeoutException: Message: \nStacktrace:\n#0 0x5603d009efe3 <unknown>\n#1 0x5603cfdddd36 <unknown>\n#2 0x5603cfe1ac4d <unknown>\n#3 0x5603cfe1ad61 <unknown>\n#4 0x5603cfe566a4 <unknown>\n#5 0x5603cfe3b8ed <unknown>\n#6 0x5603cfe54232 <unknown>\n#7 0x5603cfe3b693 <unknown>\n#8 0x5603cfe0e03a <unknown>\n#9 0x5603cfe0f17e <unknown>\n#10 0x5603d0060dbd <unknown>\n#11 0x5603d0064c6c <unknown>\n#12 0x5603d006e4b0 <unknown>\n#13 0x5603d0065d63 <unknown>\n#14 0x5603d0038c35 <unknown>\n#15 0x5603d0089138 <unknown>\n#16 0x5603d00892c7 <unknown>\n#17 0x5603d0097093 <unknown>\n#18 0x7fd9f8bf7b43 <unknown>","time":{"start":1683292668895,"stop":1683292668895,"duration":0}}]},"156d8f497cfb2d6c2f80e1b63e77e862":{"statistic":{"failed":0,"broken":1,"skipped":0,"passed":0,"unknown":0,"total":1},"items":[{"uid":"58602daa586fff46","reportUrl":"https://alyaothman14.github.io/selenium-python/2//#testresult/58602daa586fff46","status":"broken","statusDetails":"selenium.common.exceptions.TimeoutException: Message:","time":{"start":1683292709685,"stop":1683292740927,"duration":31242}}]},"b3fd85ef19f2a584247374779ac47c1a":{"statistic":{"failed":0,"broken":1,"skipped":0,"passed":0,"unknown":0,"total":1},"items":[{"uid":"b5c19e9faf1cd042","reportUrl":"https://alyaothman14.github.io/selenium-python/2//#testresult/b5c19e9faf1cd042","status":"broken","statusDetails":"urllib3.exceptions.MaxRetryError: HTTPConnectionPool(host='localhost', port=59837): Max retries exceeded with url: /session/e1872a38dcd6512227cfce6703fa25fd/window (Caused by NewConnectionError('<urllib3.connection.HTTPConnection object at 0x7f75b3219750>: Failed to establish a new connection: [Errno 111] Connection refused'))","time":{"start":1683292744094,"stop":1683292745620,"duration":1526}}]}}