{"3f4d1291f67c4cd8748668c4b83c4596":{"statistic":{"failed":0,"broken":1,"skipped":0,"passed":0,"unknown":0,"total":1},"items":[{"uid":"87cd372d4088e2e8","reportUrl":"https://alyaothman14.github.io/selenium-python/4//#testresult/87cd372d4088e2e8","status":"broken","statusDetails":"urllib3.exceptions.MaxRetryError: HTTPConnectionPool(host='localhost', port=49855): Max retries exceeded with url: /session/e28b119e619543395352fac5c625d5bd/window (Caused by NewConnectionError('<urllib3.connection.HTTPConnection object at 0x7f61e0fa7880>: Failed to establish a new connection: [Errno 111] Connection refused'))","time":{"start":1683293274819,"stop":1683293275469,"duration":650}}]},"326de79410bf5e80a41e2bbea3e523a5":{"statistic":{"failed":0,"broken":1,"skipped":0,"passed":0,"unknown":0,"total":1},"items":[{"uid":"43f94b9da29f778f","reportUrl":"https://alyaothman14.github.io/selenium-python/4//#testresult/43f94b9da29f778f","status":"broken","statusDetails":"selenium.common.exceptions.TimeoutException: Message:","time":{"start":1683293434142,"stop":1683293464503,"duration":30361}}]},"ce62b6e95f8e8da009fe6f309ba4fc9a":{"statistic":{"failed":0,"broken":1,"skipped":0,"passed":0,"unknown":0,"total":1},"items":[{"uid":"348e09c51c384f94","reportUrl":"https://alyaothman14.github.io/selenium-python/4//#testresult/348e09c51c384f94","status":"broken","statusDetails":"urllib3.exceptions.MaxRetryError: HTTPConnectionPool(host='localhost', port=33673): Max retries exceeded with url: /session/655516707942b98e0e6a824f26f5b896/window (Caused by NewConnectionError('<urllib3.connection.HTTPConnection object at 0x7f61e110dab0>: Failed to establish a new connection: [Errno 111] Connection refused'))","time":{"start":1683293226534,"stop":1683293227770,"duration":1236}}]},"156d8f497cfb2d6c2f80e1b63e77e862":{"statistic":{"failed":0,"broken":1,"skipped":0,"passed":0,"unknown":0,"total":1},"items":[{"uid":"2af8ad8ee93f5284","reportUrl":"https://alyaothman14.github.io/selenium-python/4//#testresult/2af8ad8ee93f5284","status":"broken","statusDetails":"selenium.common.exceptions.TimeoutException: Message:","time":{"start":1683293347297,"stop":1683293378157,"duration":30860}}]},"b3fd85ef19f2a584247374779ac47c1a":{"statistic":{"failed":0,"broken":1,"skipped":0,"passed":0,"unknown":0,"total":1},"items":[{"uid":"1c21943cc04a0f41","reportUrl":"https://alyaothman14.github.io/selenium-python/4//#testresult/1c21943cc04a0f41","status":"broken","statusDetails":"urllib3.exceptions.MaxRetryError: HTTPConnectionPool(host='localhost', port=39687): Max retries exceeded with url: /session/b4374593ef44f0d4db7d52290500e340/window (Caused by NewConnectionError('<urllib3.connection.HTTPConnection object at 0x7f61e251d870>: Failed to establish a new connection: [Errno 111] Connection refused'))","time":{"start":1683293419582,"stop":1683293421178,"duration":1596}}]}}