WARNING  urllib3.connectionpool:connectionpool.py:812 Retrying (Retry(total=2, connect=None, read=None, redirect=None, status=None)) after connection broken by 'NewConnectionError('<urllib3.connection.HTTPConnection object at 0x7fbc25a693c0>: Failed to establish a new connection: [Errno 111] Connection refused')': /session/19550d82327b4e9c34bcedd09c8e170c/se/log
WARNING  urllib3.connectionpool:connectionpool.py:812 Retrying (Retry(total=1, connect=None, read=None, redirect=None, status=None)) after connection broken by 'NewConnectionError('<urllib3.connection.HTTPConnection object at 0x7fbc25a6a530>: Failed to establish a new connection: [Errno 111] Connection refused')': /session/19550d82327b4e9c34bcedd09c8e170c/se/log
WARNING  urllib3.connectionpool:connectionpool.py:812 Retrying (Retry(total=0, connect=None, read=None, redirect=None, status=None)) after connection broken by 'NewConnectionError('<urllib3.connection.HTTPConnection object at 0x7fbc25a6a8f0>: Failed to establish a new connection: [Errno 111] Connection refused')': /session/19550d82327b4e9c34bcedd09c8e170c/se/log